Workbook

Sheet Summary
A1: Closebook — 3-Year Summary ($)
A2: Every number on this sheet is a formula driven by the Assumptions sheet.
A4: Metric | B4: Year 1 | C4: Year 2 | D4: Year 3
A5: Clients at year end | B5: =INDEX(Monthly!$C$13:$AL$13,12) -> 149.3256 | C5: =INDEX(Monthly!$C$13:$AL$13,24) -> 666.09511 | D5: =INDEX(Monthly!$C$13:$AL$13,36) -> 1566.5321
A6: CPA partner firms at year end | B6: =INDEX(Monthly!$C$8:$AL$8,12) -> 6 | C6: =INDEX(Monthly!$C$8:$AL$8,24) -> 30 | D6: =INDEX(Monthly!$C$8:$AL$8,36) -> 66
A7: New clients won | B7: =SUMIF(Monthly!$C$4:$AL$4,1,Monthly!$C$10:$AL$10) -> 166.00834 | C7: =SUMIF(Monthly!$C$4:$AL$4,2,Monthly!$C$10:$AL$10) -> 643.97352 | D7: =SUMIF(Monthly!$C$4:$AL$4,3,Monthly!$C$10:$AL$10) -> 1278.2241
A8: Exit MRR (subscription) | B8: =INDEX(Monthly!$C$17:$AL$17,12) -> 68540.45 | C8: =INDEX(Monthly!$C$17:$AL$17,24) -> 305737.66 | D8: =INDEX(Monthly!$C$17:$AL$17,36) -> 719038.25
A9: Exit ARR (MRR × 12) | B9: =B8*12 -> 822485.39 | C9: =C8*12 -> 3668851.9 | D9: =D8*12 -> 8628459
A11: Net revenue | B11: =SUMIF(Monthly!$C$4:$AL$4,1,Monthly!$C$20:$AL$20) -> 484842.11 | C11: =SUMIF(Monthly!$C$4:$AL$4,2,Monthly!$C$20:$AL$20) -> 2709028.6 | D11: =SUMIF(Monthly!$C$4:$AL$4,3,Monthly!$C$20:$AL$20) -> 6990834.5
A12: Gross profit | B12: =SUMIF(Monthly!$C$4:$AL$4,1,Monthly!$C$29:$AL$29) -> 374806.83 | C12: =SUMIF(Monthly!$C$4:$AL$4,2,Monthly!$C$29:$AL$29) -> 2150251.2 | D12: =SUMIF(Monthly!$C$4:$AL$4,3,Monthly!$C$29:$AL$29) -> 5618584
A13: Gross margin % | B13: =IF(B11=0,0,B12/B11) -> 0.77304926 | C13: =IF(C11=0,0,C12/C11) -> 0.79373513 | D13: =IF(D11=0,0,D12/D11) -> 0.8037072
A14: Operating expenses | B14: =SUMIF(Monthly!$C$4:$AL$4,1,Monthly!$C$36:$AL$36) -> 891839.59 | C14: =SUMIF(Monthly!$C$4:$AL$4,2,Monthly!$C$36:$AL$36) -> 1970744.8 | D14: =SUMIF(Monthly!$C$4:$AL$4,3,Monthly!$C$36:$AL$36) -> 2931602.8
A15: EBITDA | B15: =SUMIF(Monthly!$C$4:$AL$4,1,Monthly!$C$37:$AL$37) -> -517032.76 | C15: =SUMIF(Monthly!$C$4:$AL$4,2,Monthly!$C$37:$AL$37) -> 179506.4 | D15: =SUMIF(Monthly!$C$4:$AL$4,3,Monthly!$C$37:$AL$37) -> 2686981.2
A16: Closing cash | B16: =INDEX(Monthly!$C$42:$AL$42,12) -> 1032967.2 | C16: =INDEX(Monthly!$C$42:$AL$42,24) -> 1212473.6 | D16: =INDEX(Monthly!$C$42:$AL$42,36) -> 3899454.8
A18: Key results
A19: Lowest cash balance | B19: =MIN(Monthly!$C$42:$AL$42) -> 894027.63 | E19: If negative, the raise is too small or costs too high.
A20: Month cash runs out | B20: =IF(MIN(Monthly!$C$46:$AL$46)=999,"Not within 36 months",MIN(Monthly!$C$46:$AL$46)) -> Not within 36 months
A21: First month with positive EBITDA | B21: =IF(MIN(Monthly!$C$47:$AL$47)=999,"Not within 36 months",MIN(Monthly!$C$47:$AL$47)) -> 18
A22: Peak monthly burn | B22: =MAX(Monthly!$C$43:$AL$43) -> 58521.366
A23: Blended price per client (ARPA) | B23: =Assumptions!$B$13 -> 459

Sheet Unit Economics
A1: Closebook — Unit Economics (per client, steady state)
A3: Revenue per client per month (ARPA) | B3: =Assumptions!$B$13 -> 459
A4: Payment processing per client | B4: =B3*Assumptions!$B$37 -> 13.77
A5: Service cost per client (CPA + AI + data) | B5: =Assumptions!$B$33+Assumptions!$B$34+Assumptions!$B$35 -> 53
A6: Contribution per client per month | B6: =B3-B4-B5 -> 392.23
A7: Contribution margin % | B7: =IF(B3=0,0,B6/B3) -> 0.85453159 | C7: Deck target gross margin: 85–90%.
A8: Expected client lifetime (months) | B8: =IF(Assumptions!$B$30=0,0,1/Assumptions!$B$30) -> 33.333333 | C8: 1 ÷ monthly churn.
A9: Lifetime value (contribution) | B9: =B6*B8 -> 13074.333 | C9: Excludes catch-up revenue, so it is conservative.
A10: Direct CAC | B10: =Assumptions!$B$22 -> 1500
A11: LTV ÷ CAC | B11: =IF(B10=0,0,B9/B10) -> 8.7162222 | C11: Above 3x is generally considered healthy.
A12: CAC payback (months) | B12: =IF(B6<=0,0,B10/B6) -> 3.8242868 | C12: Months of contribution to earn back acquisition cost.

Sheet Assumptions
A1: Closebook — Financial Model Assumptions
A2: Legend: blue = input you can change · yellow fill = key assumption or placeholder to confirm · black = formula · green = link to another sheet. All figures are founder estimates, not sourced data.
A5: Pricing ($ per client per month)
A6: Starter plan price | B6: 299 | D6: From pitch deck pricing.
A7: Growth plan price | B7: 499 | D7: From pitch deck pricing.
A8: Pro plan price | B8: 899 | D8: From pitch deck pricing.
A9: Plan mix: Starter | B9: 0.5 | D9: Share of clients on each plan; must sum to 100%.
A10: Plan mix: Growth | B10: 0.35
A11: Plan mix: Pro | B11: 0.15
A12: Plan mix check (must be 100%) | B12: =$B$9+$B$10+$B$11 -> 1
A13: Blended price per client (ARPA) | B13: =$B$6*$B$9+$B$7*$B$10+$B$8*$B$11 -> 459
A14: Catch-up attach rate (share of new clients) | B14: 0.4 | D14: Clients who buy one-time catch-up bookkeeping when they join.
A15: Average catch-up price | B15: 2500 | D15: Deck range: $1,500–$5,000 one-time.
A17: Customer acquisition
A18: Direct new clients in month 1 | B18: 5 | D18: Concierge phase: hand-served Shopify sellers.
A19: Direct new-client growth per month, year 1 | B19: 0.15 | D19: Month-over-month growth in new clients.
A20: Direct new-client growth per month, year 2 | B20: 0.06
A21: Direct new-client growth per month, year 3 | B21: 0.03
A22: Direct CAC (marketing $ per new direct client) | B22: 1500 | D22: Paid + content cost to win one direct client.
A23: Fixed marketing spend per month | B23: 2000 | D23: Content, tools, events.
A24: CPA partner program starts (month #) | B24: 7 | D24: Deck roadmap: white-label in months 9–18; pilots earlier.
A25: New CPA partner firms per month, year 1 | B25: 1 | D25: Applies from the start month.
A26: New CPA partner firms per month, year 2 | B26: 2
A27: New CPA partner firms per month, year 3 | B27: 3
A28: New clients per active partner per month | B28: 1 | D28: Deck: one firm can bring 20–100 clients over time.
A29: Revenue share paid to partner firms | B29: 0.2 | D29: Of subscription revenue from partner-sourced clients.
A30: Monthly client churn | B30: 0.03 | D30: Deck target: under 2%; modelled conservatively.
A32: Cost of revenue
A33: CPA review cost per client per month | B33: 20 | D33: ~30 min/month at ~$40/hr (tech spec target).
A34: AI / LLM cost per client per month | B34: 25 | D34: Deck range: $15–30.
A35: Bank and data feed cost per client per month | B35: 8 | D35: Deck range: $5–10.
A36: Catch-up delivery cost (% of catch-up revenue) | B36: 0.35 | D36: Contract bookkeeper time for back months.
A37: Payment processing (% of revenue) | B37: 0.03 | D37: Card processing on subscriptions.
A39: Operating expenses
A40: Payroll burden (taxes and benefits, % of salary) | B40: 0.2
A41: G&A base per month (software, legal, insurance) | B41: 4000
A42: G&A per client per month (support tools) | B42: 5
A44: Funding
A45: Starting cash | B45: 50000 | D45: Founders' cash before the round. Placeholder.
A46: Pre-seed raise amount | B46: 1500000 | D46: Deck shows [$__]: replace with the real target.
...

Sheet Monthly
A1: Closebook — Monthly Projection (36 months, $)
A3: Month # | C3: 1 | D3: 2 | E3: 3 | F3: 4 | G3: 5 | H3: 6 | I3: 7 | J3: 8 | K3: 9 | L3: 10 | M3: 11 | N3: 12 | O3: 13 | P3: 14 | Q3: 15 | R3: 16 | S3: 17 | T3: 18 | U3: 19 | V3: 20 | W3: 21 | X3: 22 | Y3: 23 | Z3: 24 | AA3: 25 | AB3: 26 | AC3: 27 | AD3: 28 | AE3: 29 | AF3: 30 | AG3: 31 | AH3: 32 | AI3: 33 | AJ3: 34 | AK3: 35 | AL3: 36
A4: Year | C4: =ROUNDUP(C$3/12,0) -> 1 | D4: =ROUNDUP(D$3/12,0) -> 1 | E4: =ROUNDUP(E$3/12,0) -> 1 | F4: =ROUNDUP(F$3/12,0) -> 1 | G4: =ROUNDUP(G$3/12,0) -> 1 | H4: =ROUNDUP(H$3/12,0) -> 1 | I4: =ROUNDUP(I$3/12,0) -> 1 | J4: =ROUNDUP(J$3/12,0) -> 1 | ... AL4: =ROUNDUP(AL$3/12,0) -> 3
A6: Customers
A7: New direct clients | C7: =Assumptions!$B$18 -> 5 | D7: =C7*(1+INDEX(Assumptions!$B$19:$B$21,D$4)) -> 5.75 | E7: =D7*(1+INDEX(Assumptions!$B$19:$B$21,E$4)) -> 6.6125 | F7: =E7*(1+INDEX(Assumptions!$B$19:$B$21,F$4)) -> 7.604375 | G7: =F7*(1+INDEX(Assumptions!$B$19:$B$21,G$4)) -> 8.7450313 | H7: =G7*(1+INDEX(Assumptions!$B$19:$B$21,H$4)) -> 10.056786 | I7: =H7*(1+INDEX(Assumptions!$B$19:$B$21,I$4)) -> 11.565304 | J7: =I7*(1+INDEX(Assumptions!$B$19:$B$21,J$4)) -> 13.300099 | K7: =J7*(1+INDEX(Assumptions!$B$19:$B$21,K$4)) -> 15.295114 | ... AL7: =AK7*(1+INDEX(Assumptions!$B$19:$B$21,AL$4)) -> 66.736485
A8: Active CPA partner firms | C8: =0+IF(C$3>=Assumptions!$B$24,INDEX(Assumptions!$B$25:$B$27,C$4),0) -> 0 | D8: =C8+IF(D$3>=Assumptions!$B$24,INDEX(Assumptions!$B$25:$B$27,D$4),0) -> 0 | E8: =D8+IF(E$3>=Assumptions!$B$24,INDEX(Assumptions!$B$25:$B$27,E$4),0) -> 0 | F8: =E8+IF(F$3>=Assumptions!$B$24,INDEX(Assumptions!$B$25:$B$27,F$4),0) -> 0 | G8: =F8+IF(G$3>=Assumptions!$B$24,INDEX(Assumptions!$B$25:$B$27,G$4),0) -> 0 | H8: =G8+IF(H$3>=Assumptions!$B$24,INDEX(Assumptions!$B$25:$B$27,H$4),0) -> 0 | I8: =H8+IF(I$3>=Assumptions!$B$24,INDEX(Assumptions!$B$25:$B$27,I$4),0) -> 1 | J8: =I8+IF(J$3>=Assumptions!$B$24,INDEX(Assumptions!$B$25:$B$27,J$4),0) -> 2 | K8: =J8+IF(K$3>=Assumptions!$B$24,INDEX(Assumptions!$B$25:$B$27,K$4),0) -> 3 | ... AL8: =AK8+IF(AL$3>=Assumptions!$B$24,INDEX(Assumptions!$B$25:$B$27,AL$4),0) -> 66
A9: New partner-sourced clients | C9: =C8*Assumptions!$B$28 -> 0 | D9: =D8*Assumptions!$B$28 -> 0 | E9: =E8*Assumptions!$B$28 -> 0 | F9: =F8*Assumptions!$B$28 -> 0 | G9: =G8*Assumptions!$B$28 -> 0 | H9: =H8*Assumptions!$B$28 -> 0 | I9: =I8*Assumptions!$B$28 -> 1 | J9: =J8*Assumptions!$B$28 -> 2 | ... AL9: =AL8*Assumptions!$B$28 -> 66
A10: Total new clients | C10: =C7+C9 -> 5 | D10: =D7+D9 -> 5.75 | E10: =E7+E9 -> 6.6125 | F10: =F7+F9 -> 7.604375 | G10: =G7+G9 -> 8.7450313 | H10: =H7+H9 -> 10.056786 | I10: =I7+I9 -> 12.565304 | J10: =J7+J9 -> 15.300099 | ... AL10: =AL7+AL9 -> 132.73648
A11: Direct clients (end of month) | C11: =C7 -> 5 | D11: =C11*(1-Assumptions!$B$30)+D7 -> 10.6 | E11: =D11*(1-Assumptions!$B$30)+E7 -> 16.8945 | F11: =E11*(1-Assumptions!$B$30)+F7 -> 23.99204 | G11: =F11*(1-Assumptions!$B$30)+G7 -> 32.01731 | H11: =G11*(1-Assumptions!$B$30)+H7 -> 41.113577 | I11: =H11*(1-Assumptions!$B$30)+I7 -> 51.445473 | J11: =I11*(1-Assumptions!$B$30)+J7 -> 63.202208 | K11: =J11*(1-Assumptions!$B$30)+K7 -> 76.601256 | ... AL11: =AK11*(1-Assumptions!$B$30)+AL7 -> 901.00029
A12: Partner clients (end of month) | C12: =C9 -> 0 | D12: =C12*(1-Assumptions!$B$30)+D9 -> 0 | E12: =D12*(1-Assumptions!$B$30)+E9 -> 0 | F12: =E12*(1-Assumptions!$B$30)+F9 -> 0 | G12: =F12*(1-Assumptions!$B$30)+G9 -> 0 | H12: =G12*(1-Assumptions!$B$30)+H9 -> 0 | I12: =H12*(1-Assumptions!$B$30)+I9 -> 1 | J12: =I12*(1-Assumptions!$B$30)+J9 -> 2.97 | K12: =J12*(1-Assumptions!$B$30)+K9 -> 5.8809 | ... AL12: =AK12*(1-Assumptions!$B$30)+AL9 -> 665.53184
A13: Total clients (end of month) | C13: =C11+C12 -> 5 | D13: =D11+D12 -> 10.6 | E13: =E11+E12 -> 16.8945 | F13: =F11+F12 -> 23.99204 | G13: =G11+G12 -> 32.01731 | H13: =H11+H12 -> 41.113577 | I13: =I11+I12 -> 52.445473 | J13: =J11+J12 -> 66.172208 | ... AL13: =AL11+AL12 -> 1566.5321
A14: Clients churned | C14: =0 -> 0 | D14: =(C11+C12)*Assumptions!$B$30 -> 0.15 | E14: =(D11+D12)*Assumptions!$B$30 -> 0.318 | F14: =(E11+E12)*Assumptions!$B$30 -> 0.506835 | G14: =(F11+F12)*Assumptions!$B$30 -> 0.7197612 | H14: =(G11+G12)*Assumptions!$B$30 -> 0.9605193 | I14: =(H11+H12)*Assumptions!$B$30 -> 1.2334073 | J14: =(I11+I12)*Assumptions!$B$30 -> 1.5733642 | K14: =(J11+J12)*Assumptions!$B$30 -> 1.9851663 | ... AL14: =(AK11+AK12)*Assumptions!$B$30 -> 44.344195
A16: Revenue
A17: Subscription revenue (MRR) | C17: =C13*Assumptions!$B$13 -> 2295 | D17: =D13*Assumptions!$B$13 -> 4865.4 | E17: =E13*Assumptions!$B$13 -> 7754.5755 | F17: =F13*Assumptions!$B$13 -> 11012.346 | G17: =G13*Assumptions!$B$13 -> 14695.945 | H17: =H13*Assumptions!$B$13 -> 18871.132 | I17: =I13*Assumptions!$B$13 -> 24072.472 | J17: =J13*Assumptions!$B$13 -> 30373.044 | ... AL17: =AL13*Assumptions!$B$13 -> 719038.25
A18: Catch-up revenue (one-time) | C18: =C10*Assumptions!$B$14*Assumptions!$B$15 -> 5000 | D18: =D10*Assumptions!$B$14*Assumptions!$B$15 -> 5750 | E18: =E10*Assumptions!$B$14*Assumptions!$B$15 -> 6612.5 | F18: =F10*Assumptions!$B$14*Assumptions!$B$15 -> 7604.375 | G18: =G10*Assumptions!$B$14*Assumptions!$B$15 -> 8745.0312 | H18: =H10*Assumptions!$B$14*Assumptions!$B$15 -> 10056.786 | I18: =I10*Assumptions!$B$14*Assumptions!$B$15 -> 12565.304 | J18: =J10*Assumptions!$B$14*Assumptions!$B$15 -> 15300.099 | ... AL18: =AL10*Assumptions!$B$14*Assumptions!$B$15 -> 132736.48
A19: Less: partner revenue share | C19: =-C12*Assumptions!$B$13*Assumptions!$B$29 -> 0 | D19: =-D12*Assumptions!$B$13*Assumptions!$B$29 -> 0 | E19: =-E12*Assumptions!$B$13*Assumptions!$B$29 -> 0 | F19: =-F12*Assumptions!$B$13*Assumptions!$B$29 -> 0 | G19: =-G12*Assumptions!$B$13*Assumptions!$B$29 -> 0 | H19: =-H12*Assumptions!$B$13*Assumptions!$B$29 -> 0 | I19: =-I12*Assumptions!$B$13*Assumptions!$B$29 -> -91.8 | J19: =-J12*Assumptions!$B$13*Assumptions!$B$29 -> -272.646 | ... AL19: =-AL12*Assumptions!$B$13*Assumptions!$B$29 -> -61095.822
A20: Net revenue | C20: =C17+C18+C19 -> 7295 | D20: =D17+D18+D19 -> 10615.4 | E20: =E17+E18+E19 -> 14367.076 | F20: =F17+F18+F19 -> 18616.721 | G20: =G17+G18+G19 -> 23440.977 | H20: =H17+H18+H19 -> 28927.918 | I20: =I17+I18+I19 -> 36545.976 | J20: =J17+J18+J19 -> 45400.497 | ... AL20: =AL17+AL18+AL19 -> 790678.91
A22: Cost of revenue
A23: CPA review | C23: =C13*Assumptions!$B$33 -> 100 | D23: =D13*Assumptions!$B$33 -> 212 | E23: =E13*Assumptions!$B$33 -> 337.89 | F23: =F13*Assumptions!$B$33 -> 479.8408 | G23: =G13*Assumptions!$B$33 -> 640.3462 | H23: =H13*Assumptions!$B$33 -> 822.27153 | I23: =I13*Assumptions!$B$33 -> 1048.9095 | J23: =J13*Assumptions!$B$33 -> 1323.4442 | ... AL23: =AL13*Assumptions!$B$33 -> 31330.643
A24: AI / LLM | C24: =C13*Assumptions!$B$34 -> 125 | D24: =D13*Assumptions!$B$34 -> 265 | E24: =E13*Assumptions!$B$34 -> 422.3625 | F24: =F13*Assumptions!$B$34 -> 599.801 | G24: =G13*Assumptions!$B$34 -> 800.43275 | H24: =H13*Assumptions!$B$34 -> 1027.8394 | I24: =I13*Assumptions!$B$34 -> 1311.1368 | J24: =J13*Assumptions!$B$34 -> 1654.3052 | ... AL24: =AL13*Assumptions!$B$34 -> 39163.303
A25: Bank and data feeds | C25: =C13*Assumptions!$B$35 -> 40 | D25: =D13*Assumptions!$B$35 -> 84.8 | E25: =E13*Assumptions!$B$35 -> 135.156 | F25: =F13*Assumptions!$B$35 -> 191.93632 | G25: =G13*Assumptions!$B$35 -> 256.13848 | H25: =H13*Assumptions!$B$35 -> 328.90861 | I25: =I13*Assumptions!$B$35 -> 419.56379 | J25: =J13*Assumptions!$B$35 -> 529.37767 | ... AL25: =AL13*Assumptions!$B$35 -> 12532.257
A26: Catch-up delivery | C26: =C18*Assumptions!$B$36 -> 1750 | D26: =D18*Assumptions!$B$36 -> 2012.5 | E26: =E18*Assumptions!$B$36 -> 2314.375 | F26: =F18*Assumptions!$B$36 -> 2661.5312 | G26: =G18*Assumptions!$B$36 -> 3060.7609 | H26: =H18*Assumptions!$B$36 -> 3519.8751 | I26: =I18*Assumptions!$B$36 -> 4397.8563 | J26: =J18*Assumptions!$B$36 -> 5355.0348 | ... AL26: =AL18*Assumptions!$B$36 -> 46457.77
A27: Payment processing | C27: =C20*Assumptions!$B$37 -> 218.85 | D27: =D20*Assumptions!$B$37 -> 318.462 | E27: =E20*Assumptions!$B$37 -> 431.01227 | F27: =F20*Assumptions!$B$37 -> 558.50164 | G27: =G20*Assumptions!$B$37 -> 703.2293 | H27: =H20*Assumptions!$B$37 -> 867.83753 | I27: =I20*Assumptions!$B$37 -> 1096.3793 | J27: =J20*Assumptions!$B$37 -> 1362.0149 | ... AL27: =AL20*Assumptions!$B$37 -> 23720.367
A28: Total cost of revenue | C28: =SUM(C23:C27) -> 2233.85 | D28: =SUM(D23:D27) -> 2892.762 | E28: =SUM(E23:E27) -> 3640.7958 | F28: =SUM(F23:F27) -> 4491.611 | G28: =SUM(G23:G27) -> 5460.9077 | H28: =SUM(H23:H27) -> 6566.7322 | I28: =SUM(I23:I27) -> 8273.8457 | J28: =SUM(J23:J27) -> 10224.177 | ... AL28: =SUM(AL23:AL27) -> 153204.34
A29: Gross profit | C29: =C20-C28 -> 5061.15 | D29: =D20-D28 -> 7722.638 | E29: =E20-E28 -> 10726.28 | F29: =F20-F28 -> 14125.11 | G29: =G20-G28 -> 17980.069 | H29: =H20-H28 -> 22361.185 | I29: =I20-I28 -> 28272.13 | J29: =J20-J28 -> 35176.32 | ... AL29: =AL20-AL28 -> 637474.57
A30: Gross margin % | C30: =IF(C20=0,0,C29/C20) -> 0.69378341 | D30: =IF(D20=0,0,D29/D20) -> 0.72749383 | E30: =IF(E20=0,0,E29/E20) -> 0.74658755 | F30: =IF(F20=0,0,F29/F20) -> 0.75873244 | G30: =IF(G20=0,0,G29/G20) -> 0.76703583 | H30: =IF(H20=0,0,H29/H20) -> 0.77299672 | I30: =IF(I20=0,0,I29/I20) -> 0.77360447 | J30: =IF(J20=0,0,J29/J20) -> 0.77480033 | ... AL30: =IF(AL20=0,0,AL29/AL20) -> 0.80623697
A32: Operating expenses
A33: Payroll (incl. burden) | C33: =SUMPRODUCT(--(Assumptions!$C$51:$C$62<=C$3),Assumptions!$B$51:$B$62)*(1+Assumptions!$B$40) -> 24000 | D33: =SUMPRODUCT(--(Assumptions!$C$51:$C$62<=D$3),Assumptions!$B$51:$B$62)*(1+Assumptions!$B$40) -> 24000 | E33: =SUMPRODUCT(--(Assumptions!$C$51:$C$62<=E$3),Assumptions!$B$51:$B$62)*(1+Assumptions!$B$40) -> 24000 | F33: =SUMPRODUCT(--(Assumptions!$C$51:$C$62<=F$3),Assumptions!$B$51:$B$62)*(1+Assumptions!$B$40) -> 39600 | G33: =SUMPRODUCT(--(Assumptions!$C$51:$C$62<=G$3),Assumptions!$B$51:$B$62)*(1+Assumptions!$B$40) -> 39600 | H33: =SUMPRODUCT(--(Assumptions!$C$51:$C$62<=H$3),Assumptions!$B$51:$B$62)*(1+Assumptions!$B$40) -> 50400 | I33: =SUMPRODUCT(--(Assumptions!$C$51:$C$62<=I$3),Assumptions!$B$51:$B$62)*(1+Assumptions!$B$40) -> 50400 | J33: =SUMPRODUCT(--(Assumptions!$C$51:$C$62<=J$3),Assumptions!$B$51:$B$62)*(1+Assumptions!$B$40) -> 50400 | ... AL33: =SUMPRODUCT(--(Assumptions!$C$51:$C$62<=AL$3),Assumptions!$B$51:$B$62)*(1+Assumptions!$B$40) -> 151200
A34: Marketing | C34: =C7*Assumptions!$B$22+Assumptions!$B$23 -> 9500 | D34: =D7*Assumptions!$B$22+Assumptions!$B$23 -> 10625 | E34: =E7*Assumptions!$B$22+Assumptions!$B$23 -> 11918.75 | F34: =F7*Assumptions!$B$22+Assumptions!$B$23 -> 13406.562 | G34: =G7*Assumptions!$B$22+Assumptions!$B$23 -> 15117.547 | H34: =H7*Assumptions!$B$22+Assumptions!$B$23 -> 17085.179 | I34: =I7*Assumptions!$B$22+Assumptions!$B$23 -> 19347.956 | J34: =J7*Assumptions!$B$22+Assumptions!$B$23 -> 21950.149 | ... AL34: =AL7*Assumptions!$B$22+Assumptions!$B$23 -> 102104.73
A35: General & administrative | C35: =Assumptions!$B$41+C13*Assumptions!$B$42 -> 4025 | D35: =Assumptions!$B$41+D13*Assumptions!$B$42 -> 4053 | E35: =Assumptions!$B$41+E13*Assumptions!$B$42 -> 4084.4725 | F35: =Assumptions!$B$41+F13*Assumptions!$B$42 -> 4119.9602 | G35: =Assumptions!$B$41+G13*Assumptions!$B$42 -> 4160.0866 | H35: =Assumptions!$B$41+H13*Assumptions!$B$42 -> 4205.5679 | I35: =Assumptions!$B$41+I13*Assumptions!$B$42 -> 4262.2274 | J35: =Assumptions!$B$41+J13*Assumptions!$B$42 -> 4330.861 | ... AL35: =Assumptions!$B$41+AL13*Assumptions!$B$42 -> 11832.661
A36: Total operating expenses | C36: =SUM(C33:C35) -> 37525 | D36: =SUM(D33:D35) -> 38678 | E36: =SUM(E33:E35) -> 40003.223 | F36: =SUM(F33:F35) -> 57126.523 | G36: =SUM(G33:G35) -> 58877.633 | H36: =SUM(H33:H35) -> 71690.747 | I36: =SUM(I33:I35) -> 74010.183 | J36: =SUM(J33:J35) -> 76681.01 | ... AL36: =SUM(AL33:AL35) -> 265137.39
A37: EBITDA (operating profit) | C37: =C29-C36 -> -32463.85 | D37: =D29-D36 -> -30955.362 | E37: =E29-E36 -> -29276.943 | F37: =F29-F36 -> -43001.412 | G37: =G29-G36 -> -40897.565 | H37: =H29-H36 -> -49329.561 | I37: =I29-I36 -> -45738.053 | J37: =J29-J36 -> -41504.69 | ... AL37: =AL29-AL36 -> 372337.18
A39: Cash
A40: Opening cash | C40: =Assumptions!$B$45 -> 50000 | D40: =C42 -> 1517536.1 | E40: =D42 -> 1486580.8 | F40: =E42 -> 1457303.8 | G40: =F42 -> 1414302.4 | H40: =G42 -> 1373404.9 | I40: =H42 -> 1324075.3 | J40: =I42 -> 1278337.3 | K40: =J42 -> 1236832.6 | ... AL40: =AK42 -> 3527117.6
A41: Funding received | C41: =IF(C$3=Assumptions!$B$47,Assumptions!$B$46,0) -> 1500000 | D41: =IF(D$3=Assumptions!$B$47,Assumptions!$B$46,0) -> 0 | E41: =IF(E$3=Assumptions!$B$47,Assumptions!$B$46,0) -> 0 | F41: =IF(F$3=Assumptions!$B$47,Assumptions!$B$46,0) -> 0 | G41: =IF(G$3=Assumptions!$B$47,Assumptions!$B$46,0) -> 0 | H41: =IF(H$3=Assumptions!$B$47,Assumptions!$B$46,0) -> 0 | I41: =IF(I$3=Assumptions!$B$47,Assumptions!$B$46,0) -> 0 | J41: =IF(J$3=Assumptions!$B$47,Assumptions!$B$46,0) -> 0 | ... AL41: =IF(AL$3=Assumptions!$B$47,Assumptions!$B$46,0) -> 0
A42: Closing cash | C42: =C40+C37+C41 -> 1517536.1 | D42: =D40+D37+D41 -> 1486580.8 | E42: =E40+E37+E41 -> 1457303.8 | F42: =F40+F37+F41 -> 1414302.4 | G42: =G40+G37+G41 -> 1373404.9 | H42: =H40+H37+H41 -> 1324075.3 | I42: =I40+I37+I41 -> 1278337.3 | J42: =J40+J37+J41 -> 1236832.6 | ... AL42: =AL40+AL37+AL41 -> 3899454.8
A43: Net burn (negative EBITDA) | C43: =MAX(0,-C37) -> 32463.85 | D43: =MAX(0,-D37) -> 30955.362 | E43: =MAX(0,-E37) -> 29276.943 | F43: =MAX(0,-F37) -> 43001.412 | G43: =MAX(0,-G37) -> 40897.565 | H43: =MAX(0,-H37) -> 49329.561 | I43: =MAX(0,-I37) -> 45738.053 | J43: =MAX(0,-J37) -> 41504.69 | ... AL43: =MAX(0,-AL37) -> 0
A45: Helper flags (used by Summary)
A46: Month cash goes negative (else 999) | C46: =IF(C42<0,C$3,999) -> 999 | D46: =IF(D42<0,D$3,999) -> 999 | E46: =IF(E42<0,E$3,999) -> 999 | F46: =IF(F42<0,F$3,999) -> 999 | G46: =IF(G42<0,G$3,999) -> 999 | H46: =IF(H42<0,H$3,999) -> 999 | I46: =IF(I42<0,I$3,999) -> 999 | J46: =IF(J42<0,J$3,999) -> 999 | ... AL46: =IF(AL42<0,AL$3,999) -> 999
A47: Month EBITDA turns positive (else 999) | C47: =IF(C37>0,C$3,999) -> 999 | D47: =IF(D37>0,D$3,999) -> 999 | E47: =IF(E37>0,E$3,999) -> 999 | F47: =IF(F37>0,F$3,999) -> 999 | G47: =IF(G37>0,G$3,999) -> 999 | H47: =IF(H37>0,H$3,999) -> 999 | I47: =IF(I37>0,I$3,999) -> 999 | J47: =IF(J37>0,J$3,999) -> 999 | ... AL47: =IF(AL37>0,AL$3,999) -> 36
